{
 "cells": [
  {
   "cell_type": "code",
   "execution_count": 1,
   "metadata": {},
   "outputs": [
    {
     "name": "stdout",
     "output_type": "stream",
     "text": [
      "hiii\n"
     ]
    }
   ],
   "source": [
    "%matplotlib inline\n",
    "# Load all necessary packages\n",
    "import sys\n",
    "sys.path.append(\"../\")\n",
    "from aif360.datasets import BinaryLabelDataset\n",
    "from aif360.datasets import AdultDataset, GermanDataset, CompasDataset\n",
    "from aif360.metrics import BinaryLabelDatasetMetric\n",
    "from aif360.metrics import ClassificationMetric\n",
    "from aif360.metrics.utils import compute_boolean_conditioning_vector\n",
    "\n",
    "from aif360.algorithms.preprocessing.optim_preproc_helpers.data_preproc_functions import load_preproc_data_adult, load_preproc_data_compas, load_preproc_data_german\n",
    "\n",
    "from aif360.algorithms.inprocessing.adversarial_debiasing_dnn5 import AdversarialDebiasingDnn5\n",
    "\n",
    "from sklearn.linear_model import LogisticRegression\n",
    "from sklearn.preprocessing import StandardScaler, MaxAbsScaler\n",
    "from sklearn.metrics import accuracy_score\n",
    "\n",
    "from IPython.display import Markdown, display\n",
    "import matplotlib.pyplot as plt\n",
    "\n",
    "import tensorflow.compat.v1 as tf\n",
    "tf.disable_eager_execution()\n",
    "print('hiii')\n",
    "# Get the dataset and split into train and test\n",
    "dataset_orig = load_preproc_data_adult()\n",
    "\n",
    "privileged_groups = [{'sex': 1}]\n",
    "unprivileged_groups = [{'sex': 0}]\n",
    "\n",
    "dataset_orig_train, dataset_orig_test = dataset_orig.split([0.8], shuffle=True)\n",
    "# print out some labels, names, etc.\n",
    "sess = tf.Session()\n",
    "plain_model = AdversarialDebiasingDnn5(privileged_groups = privileged_groups,\n",
    "                          unprivileged_groups = unprivileged_groups,\n",
    "                          scope_name='plain_classifier',\n",
    "                          debias=False,\n",
    "                          sess=sess)"
   ]
  },
  {
   "cell_type": "markdown",
   "metadata": {},
   "source": [
    "### Learn plan classifier without debiasing"
   ]
  },
  {
   "cell_type": "code",
   "execution_count": 2,
   "metadata": {
    "scrolled": true
   },
   "outputs": [
    {
     "name": "stdout",
     "output_type": "stream",
     "text": [
      "WARNING:tensorflow:From D:\\PycharmProjects\\AIF360\\aif360\\algorithms\\inprocessing\\adversarial_debiasing_dnn5.py:139: The name tf.variable_scope is deprecated. Please use tf.compat.v1.variable_scope instead.\n",
      "\n",
      "WARNING:tensorflow:From D:\\PycharmProjects\\AIF360\\aif360\\algorithms\\inprocessing\\adversarial_debiasing_dnn5.py:148: The name tf.placeholder is deprecated. Please use tf.compat.v1.placeholder instead.\n",
      "\n",
      "WARNING:tensorflow:From D:\\PycharmProjects\\AIF360\\aif360\\load_model\\layer.py:23: The name tf.random_normal is deprecated. Please use tf.random.normal instead.\n",
      "\n",
      "WARNING:tensorflow:From D:\\PycharmProjects\\AIF360\\aif360\\load_model\\layer.py:25: calling reduce_sum_v1 (from tensorflow.python.ops.math_ops) with keep_dims is deprecated and will be removed in a future version.\n",
      "Instructions for updating:\n",
      "keep_dims is deprecated, use keepdims instead\n",
      "WARNING:tensorflow:From D:\\Software\\anaconda3\\envs\\newtf115\\lib\\site-packages\\tensorflow_core\\python\\ops\\nn_impl.py:183: where (from tensorflow.python.ops.array_ops) is deprecated and will be removed in a future version.\n",
      "Instructions for updating:\n",
      "Use tf.where in 2.0, which has the same broadcast rule as np.where\n",
      "WARNING:tensorflow:From D:\\PycharmProjects\\AIF360\\aif360\\algorithms\\inprocessing\\adversarial_debiasing_dnn5.py:179: The name tf.train.exponential_decay is deprecated. Please use tf.compat.v1.train.exponential_decay instead.\n",
      "\n",
      "WARNING:tensorflow:From D:\\PycharmProjects\\AIF360\\aif360\\algorithms\\inprocessing\\adversarial_debiasing_dnn5.py:181: The name tf.train.AdamOptimizer is deprecated. Please use tf.compat.v1.train.AdamOptimizer instead.\n",
      "\n",
      "WARNING:tensorflow:From D:\\PycharmProjects\\AIF360\\aif360\\algorithms\\inprocessing\\adversarial_debiasing_dnn5.py:187: The name tf.trainable_variables is deprecated. Please use tf.compat.v1.trainable_variables instead.\n",
      "\n",
      "WARNING:tensorflow:From D:\\PycharmProjects\\AIF360\\aif360\\algorithms\\inprocessing\\adversarial_debiasing_dnn5.py:227: The name tf.global_variables_initializer is deprecated. Please use tf.compat.v1.global_variables_initializer instead.\n",
      "\n",
      "WARNING:tensorflow:From D:\\PycharmProjects\\AIF360\\aif360\\algorithms\\inprocessing\\adversarial_debiasing_dnn5.py:228: The name tf.local_variables_initializer is deprecated. Please use tf.compat.v1.local_variables_initializer instead.\n",
      "\n",
      "epoch 0; iter: 0; batch classifier loss: 0.687487\n",
      "epoch 0; iter: 200; batch classifier loss: 0.389736\n",
      "epoch 1; iter: 0; batch classifier loss: 0.439247\n",
      "epoch 1; iter: 200; batch classifier loss: 0.320585\n",
      "epoch 2; iter: 0; batch classifier loss: 0.447998\n",
      "epoch 2; iter: 200; batch classifier loss: 0.418517\n",
      "epoch 3; iter: 0; batch classifier loss: 0.478368\n",
      "epoch 3; iter: 200; batch classifier loss: 0.437139\n",
      "epoch 4; iter: 0; batch classifier loss: 0.404894\n",
      "epoch 4; iter: 200; batch classifier loss: 0.419438\n",
      "epoch 5; iter: 0; batch classifier loss: 0.372289\n",
      "epoch 5; iter: 200; batch classifier loss: 0.336985\n",
      "epoch 6; iter: 0; batch classifier loss: 0.404709\n",
      "epoch 6; iter: 200; batch classifier loss: 0.417492\n",
      "epoch 7; iter: 0; batch classifier loss: 0.369820\n",
      "epoch 7; iter: 200; batch classifier loss: 0.418875\n",
      "epoch 8; iter: 0; batch classifier loss: 0.374420\n",
      "epoch 8; iter: 200; batch classifier loss: 0.361293\n",
      "epoch 9; iter: 0; batch classifier loss: 0.403906\n",
      "epoch 9; iter: 200; batch classifier loss: 0.458877\n",
      "WARNING:tensorflow:From D:\\PycharmProjects\\AIF360\\aif360\\algorithms\\inprocessing\\adversarial_debiasing_dnn5.py:103: The name tf.train.Saver is deprecated. Please use tf.compat.v1.train.Saver instead.\n",
      "\n",
      "Completed model training and saved at: ../org-model-merge/adult/9\\test.model\n",
      "WARNING:tensorflow:From D:\\PycharmProjects\\AIF360\\aif360\\algorithms\\inprocessing\\adversarial_debiasing_dnn5.py:272: The name tf.train.write_graph is deprecated. Please use tf.io.write_graph instead.\n",
      "\n"
     ]
    }
   ],
   "source": [
    "dataset_nodebiasing_train_, dataset_nodebiasing_test_ = plain_model.fit_and_pred(dataset_orig_train, dataset_orig_test)"
   ]
  },
  {
   "cell_type": "code",
   "execution_count": 2,
   "metadata": {},
   "outputs": [
    {
     "name": "stdout",
     "output_type": "stream",
     "text": [
      "WARNING:tensorflow:From D:\\PycharmProjects\\AIF360\\aif360\\algorithms\\inprocessing\\adversarial_debiasing_dnn5.py:283: The name tf.variable_scope is deprecated. Please use tf.compat.v1.variable_scope instead.\n",
      "\n",
      "WARNING:tensorflow:From D:\\PycharmProjects\\AIF360\\aif360\\algorithms\\inprocessing\\adversarial_debiasing_dnn5.py:287: The name tf.placeholder is deprecated. Please use tf.compat.v1.placeholder instead.\n",
      "\n",
      "WARNING:tensorflow:From D:\\PycharmProjects\\AIF360\\aif360\\load_model\\layer.py:23: The name tf.random_normal is deprecated. Please use tf.random.normal instead.\n",
      "\n",
      "WARNING:tensorflow:From D:\\PycharmProjects\\AIF360\\aif360\\load_model\\layer.py:25: calling reduce_sum_v1 (from tensorflow.python.ops.math_ops) with keep_dims is deprecated and will be removed in a future version.\n",
      "Instructions for updating:\n",
      "keep_dims is deprecated, use keepdims instead\n",
      "WARNING:tensorflow:From D:\\Software\\anaconda3\\envs\\newtf115\\lib\\site-packages\\tensorflow_core\\python\\ops\\nn_impl.py:183: where (from tensorflow.python.ops.array_ops) is deprecated and will be removed in a future version.\n",
      "Instructions for updating:\n",
      "Use tf.where in 2.0, which has the same broadcast rule as np.where\n",
      "WARNING:tensorflow:From D:\\PycharmProjects\\AIF360\\aif360\\algorithms\\inprocessing\\adversarial_debiasing_dnn5.py:305: The name tf.train.exponential_decay is deprecated. Please use tf.compat.v1.train.exponential_decay instead.\n",
      "\n",
      "WARNING:tensorflow:From D:\\PycharmProjects\\AIF360\\aif360\\algorithms\\inprocessing\\adversarial_debiasing_dnn5.py:307: The name tf.train.AdamOptimizer is deprecated. Please use tf.compat.v1.train.AdamOptimizer instead.\n",
      "\n",
      "WARNING:tensorflow:From D:\\PycharmProjects\\AIF360\\aif360\\algorithms\\inprocessing\\adversarial_debiasing_dnn5.py:311: The name tf.trainable_variables is deprecated. Please use tf.compat.v1.trainable_variables instead.\n",
      "\n",
      "WARNING:tensorflow:From D:\\PycharmProjects\\AIF360\\aif360\\algorithms\\inprocessing\\adversarial_debiasing_dnn5.py:334: The name tf.global_variables_initializer is deprecated. Please use tf.compat.v1.global_variables_initializer instead.\n",
      "\n",
      "WARNING:tensorflow:From D:\\PycharmProjects\\AIF360\\aif360\\algorithms\\inprocessing\\adversarial_debiasing_dnn5.py:335: The name tf.local_variables_initializer is deprecated. Please use tf.compat.v1.local_variables_initializer instead.\n",
      "\n",
      "WARNING:tensorflow:From D:\\PycharmProjects\\AIF360\\aif360\\algorithms\\inprocessing\\adversarial_debiasing_dnn5.py:520: The name tf.train.import_meta_graph is deprecated. Please use tf.compat.v1.train.import_meta_graph instead.\n",
      "\n",
      "INFO:tensorflow:Restoring parameters from ../org-model-merge/adult/9/test.model\n",
      "INFO:tensorflow:Restoring parameters from ../org-model-merge/adult/9/test.model\n",
      "ok\n"
     ]
    }
   ],
   "source": [
    "# Apply the plain model to test data\n",
    "dataset_nodebiasing_train = plain_model.predict_with_load_gra(dataset_orig_train)\n",
    "dataset_nodebiasing_test = plain_model.predict_with_load_gra(dataset_orig_test)\n",
    "print('ok')"
   ]
  },
  {
   "cell_type": "code",
   "execution_count": 3,
   "metadata": {},
   "outputs": [
    {
     "data": {
      "text/plain": "<IPython.core.display.Markdown object>",
      "text/markdown": "#### Plain model - without debiasing - dataset metrics"
     },
     "metadata": {},
     "output_type": "display_data"
    },
    {
     "name": "stdout",
     "output_type": "stream",
     "text": [
      "Train set: Difference in mean outcomes between unprivileged and privileged groups = 0.000000\n",
      "Test set: Difference in mean outcomes between unprivileged and privileged groups = 0.000000\n"
     ]
    },
    {
     "data": {
      "text/plain": "<IPython.core.display.Markdown object>",
      "text/markdown": "#### Plain model - without debiasing - classification metrics"
     },
     "metadata": {},
     "output_type": "display_data"
    },
    {
     "name": "stdout",
     "output_type": "stream",
     "text": [
      "Test set: Classification accuracy = 0.238612\n",
      "Test set: Balanced classification accuracy = 0.500000\n",
      "Test set: Disparate impact = 1.000000\n",
      "Test set: Equal opportunity difference = 0.000000\n",
      "Test set: Average odds difference = 0.000000\n",
      "Test set: Theil_index = 0.033146\n"
     ]
    }
   ],
   "source": [
    "# Metrics for the dataset from plain model (without debiasing)\n",
    "display(Markdown(\"#### Plain model - without debiasing - dataset metrics\"))\n",
    "metric_dataset_nodebiasing_train = BinaryLabelDatasetMetric(dataset_nodebiasing_train, \n",
    "                                             unprivileged_groups=unprivileged_groups,\n",
    "                                             privileged_groups=privileged_groups)\n",
    "\n",
    "print(\"Train set: Difference in mean outcomes between unprivileged and privileged groups = %f\" % metric_dataset_nodebiasing_train.mean_difference())\n",
    "\n",
    "metric_dataset_nodebiasing_test = BinaryLabelDatasetMetric(dataset_nodebiasing_test, \n",
    "                                             unprivileged_groups=unprivileged_groups,\n",
    "                                             privileged_groups=privileged_groups)\n",
    "\n",
    "print(\"Test set: Difference in mean outcomes between unprivileged and privileged groups = %f\" % metric_dataset_nodebiasing_test.mean_difference())\n",
    "\n",
    "display(Markdown(\"#### Plain model - without debiasing - classification metrics\"))\n",
    "classified_metric_nodebiasing_test = ClassificationMetric(dataset_orig_test, \n",
    "                                                 dataset_nodebiasing_test,\n",
    "                                                 unprivileged_groups=unprivileged_groups,\n",
    "                                                 privileged_groups=privileged_groups)\n",
    "print(\"Test set: Classification accuracy = %f\" % classified_metric_nodebiasing_test.accuracy())\n",
    "TPR = classified_metric_nodebiasing_test.true_positive_rate()\n",
    "TNR = classified_metric_nodebiasing_test.true_negative_rate()\n",
    "bal_acc_nodebiasing_test = 0.5*(TPR+TNR)\n",
    "print(\"Test set: Balanced classification accuracy = %f\" % bal_acc_nodebiasing_test)\n",
    "print(\"Test set: Disparate impact = %f\" % classified_metric_nodebiasing_test.disparate_impact())\n",
    "print(\"Test set: Equal opportunity difference = %f\" % classified_metric_nodebiasing_test.equal_opportunity_difference())\n",
    "print(\"Test set: Average odds difference = %f\" % classified_metric_nodebiasing_test.average_odds_difference())\n",
    "print(\"Test set: Theil_index = %f\" % classified_metric_nodebiasing_test.theil_index())"
   ]
  },
  {
   "cell_type": "markdown",
   "metadata": {},
   "source": [
    "### Apply in-processing algorithm based on adversarial learning"
   ]
  },
  {
   "cell_type": "code",
   "execution_count": 4,
   "metadata": {},
   "outputs": [],
   "source": [
    "sess.close()\n",
    "tf.reset_default_graph()\n",
    "sess = tf.Session()"
   ]
  },
  {
   "cell_type": "code",
   "execution_count": 5,
   "metadata": {},
   "outputs": [],
   "source": [
    "# Learn parameters with debias set to True\n",
    "debiased_model = AdversarialDebiasingDnn5(privileged_groups = privileged_groups,\n",
    "                          unprivileged_groups = unprivileged_groups,\n",
    "                          scope_name='debiased_classifier',\n",
    "                          debias=True,\n",
    "                          sess=sess)"
   ]
  },
  {
   "cell_type": "code",
   "execution_count": 6,
   "metadata": {
    "scrolled": true
   },
   "outputs": [
    {
     "name": "stdout",
     "output_type": "stream",
     "text": [
      "WARNING:tensorflow:From D:\\PycharmProjects\\AIF360\\aif360\\algorithms\\inprocessing\\adversarial_debiasing_dnn5.py:84: The name tf.get_variable is deprecated. Please use tf.compat.v1.get_variable instead.\n",
      "\n",
      "epoch 0; iter: 0; batch classifier loss: 0.680085; batch adversarial loss: 0.685441\n",
      "epoch 0; iter: 200; batch classifier loss: 0.464239; batch adversarial loss: 0.634047\n",
      "epoch 1; iter: 0; batch classifier loss: 0.479699; batch adversarial loss: 0.642877\n",
      "epoch 1; iter: 200; batch classifier loss: 0.437703; batch adversarial loss: 0.631411\n",
      "epoch 2; iter: 0; batch classifier loss: 0.382678; batch adversarial loss: 0.646070\n",
      "epoch 2; iter: 200; batch classifier loss: 0.429821; batch adversarial loss: 0.593361\n",
      "epoch 3; iter: 0; batch classifier loss: 0.405579; batch adversarial loss: 0.645083\n",
      "epoch 3; iter: 200; batch classifier loss: 0.520919; batch adversarial loss: 0.692524\n",
      "epoch 4; iter: 0; batch classifier loss: 0.446790; batch adversarial loss: 0.645860\n",
      "epoch 4; iter: 200; batch classifier loss: 0.457840; batch adversarial loss: 0.595926\n",
      "epoch 5; iter: 0; batch classifier loss: 0.423679; batch adversarial loss: 0.627245\n",
      "epoch 5; iter: 200; batch classifier loss: 0.566020; batch adversarial loss: 0.612867\n",
      "epoch 6; iter: 0; batch classifier loss: 0.562038; batch adversarial loss: 0.624869\n",
      "epoch 6; iter: 200; batch classifier loss: 0.357327; batch adversarial loss: 0.646399\n",
      "epoch 7; iter: 0; batch classifier loss: 0.473744; batch adversarial loss: 0.654863\n",
      "epoch 7; iter: 200; batch classifier loss: 0.472766; batch adversarial loss: 0.637157\n",
      "epoch 8; iter: 0; batch classifier loss: 0.417681; batch adversarial loss: 0.573127\n",
      "epoch 8; iter: 200; batch classifier loss: 0.511965; batch adversarial loss: 0.620871\n",
      "epoch 9; iter: 0; batch classifier loss: 0.505643; batch adversarial loss: 0.663728\n",
      "epoch 9; iter: 200; batch classifier loss: 0.559994; batch adversarial loss: 0.639356\n",
      "WARNING:tensorflow:From D:\\PycharmProjects\\AIF360\\aif360\\algorithms\\inprocessing\\adversarial_debiasing_dnn5.py:103: The name tf.train.Saver is deprecated. Please use tf.compat.v1.train.Saver instead.\n",
      "\n",
      "Completed model training and saved at: ../adebias-model-merge/adult/9\\test.model\n",
      "WARNING:tensorflow:From D:\\PycharmProjects\\AIF360\\aif360\\algorithms\\inprocessing\\adversarial_debiasing_dnn5.py:341: The name tf.train.write_graph is deprecated. Please use tf.io.write_graph instead.\n",
      "\n"
     ]
    }
   ],
   "source": [
    "dataset_debiasing_train_, dataset_debiasing_test_ = debiased_model.fit_and_pred(dataset_orig_train, dataset_orig_test)"
   ]
  },
  {
   "cell_type": "code",
   "execution_count": null,
   "metadata": {
    "pycharm": {
     "is_executing": true
    }
   },
   "outputs": [
    {
     "name": "stdout",
     "output_type": "stream",
     "text": [
      "ERROR! Session/line number was not unique in database. History logging moved to new session 121\n"
     ]
    },
    {
     "name": "stderr",
     "output_type": "stream",
     "text": [
      "ERROR:root:Internal Python error in the inspect module.\n",
      "Below is the traceback from this internal error.\n",
      "\n",
      "ERROR:root:Internal Python error in the inspect module.\n",
      "Below is the traceback from this internal error.\n",
      "\n",
      "ERROR:root:Internal Python error in the inspect module.\n",
      "Below is the traceback from this internal error.\n",
      "\n"
     ]
    },
    {
     "name": "stdout",
     "output_type": "stream",
     "text": [
      "Traceback (most recent call last):\n",
      "  File \"D:\\Software\\anaconda3\\envs\\newtf115\\lib\\site-packages\\IPython\\core\\interactiveshell.py\", line 3552, in run_code\n",
      "    exec(code_obj, self.user_global_ns, self.user_ns)\n",
      "  File \"C:\\Users\\wpkks\\AppData\\Local\\Temp\\ipykernel_29516\\2917289970.py\", line 2, in <module>\n",
      "    dataset_debiasing_train = debiased_model.predict_with_load_gra(dataset_orig_train)\n",
      "  File \"D:\\PycharmProjects\\AIF360\\aif360\\algorithms\\transformer.py\", line 27, in wrapper\n",
      "    new_dataset = func(self, *args, **kwargs)\n",
      "  File \"D:\\PycharmProjects\\AIF360\\aif360\\algorithms\\inprocessing\\adversarial_debiasing_dnn5.py\", line 513, in predict_with_load_gra\n",
      "    self.fit_without_train(dataset)\n",
      "  File \"D:\\PycharmProjects\\AIF360\\aif360\\algorithms\\transformer.py\", line 27, in wrapper\n",
      "    new_dataset = func(self, *args, **kwargs)\n",
      "  File \"D:\\PycharmProjects\\AIF360\\aif360\\algorithms\\inprocessing\\adversarial_debiasing_dnn5.py\", line 298, in fit_without_train\n",
      "    pred_protected_attributes_labels, pred_protected_attributes_logits = self._adversary_model(pred_logits, self.true_labels_ph)\n",
      "  File \"D:\\PycharmProjects\\AIF360\\aif360\\algorithms\\inprocessing\\adversarial_debiasing_dnn5.py\", line 84, in _adversary_model\n",
      "    c = tf.get_variable('c', initializer=tf.constant(1.0))\n",
      "  File \"D:\\Software\\anaconda3\\envs\\newtf115\\lib\\site-packages\\tensorflow_core\\python\\ops\\variable_scope.py\", line 1500, in get_variable\n",
      "    aggregation=aggregation)\n",
      "  File \"D:\\Software\\anaconda3\\envs\\newtf115\\lib\\site-packages\\tensorflow_core\\python\\ops\\variable_scope.py\", line 1243, in get_variable\n",
      "    aggregation=aggregation)\n",
      "  File \"D:\\Software\\anaconda3\\envs\\newtf115\\lib\\site-packages\\tensorflow_core\\python\\ops\\variable_scope.py\", line 567, in get_variable\n",
      "    aggregation=aggregation)\n",
      "  File \"D:\\Software\\anaconda3\\envs\\newtf115\\lib\\site-packages\\tensorflow_core\\python\\ops\\variable_scope.py\", line 519, in _true_getter\n",
      "    aggregation=aggregation)\n",
      "  File \"D:\\Software\\anaconda3\\envs\\newtf115\\lib\\site-packages\\tensorflow_core\\python\\ops\\variable_scope.py\", line 868, in _get_single_variable\n",
      "    (err_msg, \"\".join(traceback.format_list(tb))))\n",
      "ValueError: Variable debiased_classifier/adversary_model/c already exists, disallowed. Did you mean to set reuse=True or reuse=tf.AUTO_REUSE in VarScope? Originally defined at:\n",
      "\n",
      "  File \"D:\\Software\\anaconda3\\envs\\newtf115\\lib\\site-packages\\tensorflow_core\\python\\framework\\ops.py\", line 1748, in __init__\n",
      "    self._traceback = tf_stack.extract_stack()\n",
      "  File \"D:\\Software\\anaconda3\\envs\\newtf115\\lib\\site-packages\\tensorflow_core\\python\\framework\\ops.py\", line 3426, in _create_op_internal\n",
      "    op_def=op_def)\n",
      "  File \"D:\\Software\\anaconda3\\envs\\newtf115\\lib\\site-packages\\tensorflow_core\\python\\framework\\ops.py\", line 3357, in create_op\n",
      "    attrs, op_def, compute_device)\n",
      "  File \"D:\\Software\\anaconda3\\envs\\newtf115\\lib\\site-packages\\tensorflow_core\\python\\util\\deprecation.py\", line 507, in new_func\n",
      "    return func(*args, **kwargs)\n",
      "  File \"D:\\Software\\anaconda3\\envs\\newtf115\\lib\\site-packages\\tensorflow_core\\python\\framework\\op_def_library.py\", line 794, in _apply_op_helper\n",
      "    op_def=op_def)\n",
      "\n",
      "\n",
      "During handling of the above exception, another exception occurred:\n",
      "\n",
      "Traceback (most recent call last):\n",
      "  File \"D:\\Software\\anaconda3\\envs\\newtf115\\lib\\site-packages\\IPython\\core\\interactiveshell.py\", line 2098, in showtraceback\n",
      "    stb = value._render_traceback_()\n",
      "AttributeError: 'ValueError' object has no attribute '_render_traceback_'\n",
      "\n",
      "During handling of the above exception, another exception occurred:\n",
      "\n",
      "Traceback (most recent call last):\n",
      "  File \"D:\\Software\\anaconda3\\envs\\newtf115\\lib\\site-packages\\IPython\\core\\ultratb.py\", line 1101, in get_records\n",
      "    return _fixed_getinnerframes(etb, number_of_lines_of_context, tb_offset)\n",
      "  File \"D:\\Software\\anaconda3\\envs\\newtf115\\lib\\site-packages\\IPython\\core\\ultratb.py\", line 248, in wrapped\n",
      "    return f(*args, **kwargs)\n",
      "  File \"D:\\Software\\anaconda3\\envs\\newtf115\\lib\\site-packages\\IPython\\core\\ultratb.py\", line 281, in _fixed_getinnerframes\n",
      "    records = fix_frame_records_filenames(inspect.getinnerframes(etb, context))\n",
      "  File \"D:\\Software\\anaconda3\\envs\\newtf115\\lib\\inspect.py\", line 1502, in getinnerframes\n",
      "    frameinfo = (tb.tb_frame,) + getframeinfo(tb, context)\n",
      "  File \"D:\\Software\\anaconda3\\envs\\newtf115\\lib\\inspect.py\", line 1460, in getframeinfo\n",
      "    filename = getsourcefile(frame) or getfile(frame)\n",
      "  File \"D:\\Software\\anaconda3\\envs\\newtf115\\lib\\inspect.py\", line 696, in getsourcefile\n",
      "    if getattr(getmodule(object, filename), '__loader__', None) is not None:\n",
      "  File \"D:\\Software\\anaconda3\\envs\\newtf115\\lib\\inspect.py\", line 733, in getmodule\n",
      "    if ismodule(module) and hasattr(module, '__file__'):\n",
      "  File \"D:\\Software\\anaconda3\\envs\\newtf115\\lib\\site-packages\\tensorflow\\__init__.py\", line 50, in __getattr__\n",
      "    module = self._load()\n",
      "  File \"D:\\Software\\anaconda3\\envs\\newtf115\\lib\\site-packages\\tensorflow\\__init__.py\", line 44, in _load\n",
      "    module = _importlib.import_module(self.__name__)\n",
      "  File \"D:\\Software\\anaconda3\\envs\\newtf115\\lib\\importlib\\__init__.py\", line 127, in import_module\n",
      "    return _bootstrap._gcd_import(name[level:], package, level)\n",
      "  File \"<frozen importlib._bootstrap>\", line 1006, in _gcd_import\n",
      "  File \"<frozen importlib._bootstrap>\", line 983, in _find_and_load\n",
      "  File \"<frozen importlib._bootstrap>\", line 965, in _find_and_load_unlocked\n",
      "ModuleNotFoundError: No module named 'tensorflow_core.estimator'\n",
      "Traceback (most recent call last):\n",
      "  File \"D:\\Software\\anaconda3\\envs\\newtf115\\lib\\site-packages\\IPython\\core\\interactiveshell.py\", line 3552, in run_code\n",
      "    exec(code_obj, self.user_global_ns, self.user_ns)\n",
      "  File \"C:\\Users\\wpkks\\AppData\\Local\\Temp\\ipykernel_29516\\2917289970.py\", line 2, in <module>\n",
      "    dataset_debiasing_train = debiased_model.predict_with_load_gra(dataset_orig_train)\n",
      "  File \"D:\\PycharmProjects\\AIF360\\aif360\\algorithms\\transformer.py\", line 27, in wrapper\n",
      "    new_dataset = func(self, *args, **kwargs)\n",
      "  File \"D:\\PycharmProjects\\AIF360\\aif360\\algorithms\\inprocessing\\adversarial_debiasing_dnn5.py\", line 513, in predict_with_load_gra\n",
      "    self.fit_without_train(dataset)\n",
      "  File \"D:\\PycharmProjects\\AIF360\\aif360\\algorithms\\transformer.py\", line 27, in wrapper\n",
      "    new_dataset = func(self, *args, **kwargs)\n",
      "  File \"D:\\PycharmProjects\\AIF360\\aif360\\algorithms\\inprocessing\\adversarial_debiasing_dnn5.py\", line 298, in fit_without_train\n",
      "    pred_protected_attributes_labels, pred_protected_attributes_logits = self._adversary_model(pred_logits, self.true_labels_ph)\n",
      "  File \"D:\\PycharmProjects\\AIF360\\aif360\\algorithms\\inprocessing\\adversarial_debiasing_dnn5.py\", line 84, in _adversary_model\n",
      "    c = tf.get_variable('c', initializer=tf.constant(1.0))\n",
      "  File \"D:\\Software\\anaconda3\\envs\\newtf115\\lib\\site-packages\\tensorflow_core\\python\\ops\\variable_scope.py\", line 1500, in get_variable\n",
      "    aggregation=aggregation)\n",
      "  File \"D:\\Software\\anaconda3\\envs\\newtf115\\lib\\site-packages\\tensorflow_core\\python\\ops\\variable_scope.py\", line 1243, in get_variable\n",
      "    aggregation=aggregation)\n",
      "  File \"D:\\Software\\anaconda3\\envs\\newtf115\\lib\\site-packages\\tensorflow_core\\python\\ops\\variable_scope.py\", line 567, in get_variable\n",
      "    aggregation=aggregation)\n",
      "  File \"D:\\Software\\anaconda3\\envs\\newtf115\\lib\\site-packages\\tensorflow_core\\python\\ops\\variable_scope.py\", line 519, in _true_getter\n",
      "    aggregation=aggregation)\n",
      "  File \"D:\\Software\\anaconda3\\envs\\newtf115\\lib\\site-packages\\tensorflow_core\\python\\ops\\variable_scope.py\", line 868, in _get_single_variable\n",
      "    (err_msg, \"\".join(traceback.format_list(tb))))\n",
      "ValueError: Variable debiased_classifier/adversary_model/c already exists, disallowed. Did you mean to set reuse=True or reuse=tf.AUTO_REUSE in VarScope? Originally defined at:\n",
      "\n",
      "  File \"D:\\Software\\anaconda3\\envs\\newtf115\\lib\\site-packages\\tensorflow_core\\python\\framework\\ops.py\", line 1748, in __init__\n",
      "    self._traceback = tf_stack.extract_stack()\n",
      "  File \"D:\\Software\\anaconda3\\envs\\newtf115\\lib\\site-packages\\tensorflow_core\\python\\framework\\ops.py\", line 3426, in _create_op_internal\n",
      "    op_def=op_def)\n",
      "  File \"D:\\Software\\anaconda3\\envs\\newtf115\\lib\\site-packages\\tensorflow_core\\python\\framework\\ops.py\", line 3357, in create_op\n",
      "    attrs, op_def, compute_device)\n",
      "  File \"D:\\Software\\anaconda3\\envs\\newtf115\\lib\\site-packages\\tensorflow_core\\python\\util\\deprecation.py\", line 507, in new_func\n",
      "    return func(*args, **kwargs)\n",
      "  File \"D:\\Software\\anaconda3\\envs\\newtf115\\lib\\site-packages\\tensorflow_core\\python\\framework\\op_def_library.py\", line 794, in _apply_op_helper\n",
      "    op_def=op_def)\n",
      "\n",
      "\n",
      "During handling of the above exception, another exception occurred:\n",
      "\n",
      "Traceback (most recent call last):\n",
      "  File \"D:\\Software\\anaconda3\\envs\\newtf115\\lib\\site-packages\\IPython\\core\\interactiveshell.py\", line 2098, in showtraceback\n",
      "    stb = value._render_traceback_()\n",
      "AttributeError: 'ValueError' object has no attribute '_render_traceback_'\n",
      "\n",
      "During handling of the above exception, another exception occurred:\n",
      "\n",
      "Traceback (most recent call last):\n",
      "  File \"D:\\Software\\anaconda3\\envs\\newtf115\\lib\\site-packages\\IPython\\core\\interactiveshell.py\", line 3472, in run_ast_nodes\n",
      "    if (await self.run_code(code, result,  async_=asy)):\n",
      "  File \"D:\\Software\\anaconda3\\envs\\newtf115\\lib\\site-packages\\IPython\\core\\interactiveshell.py\", line 3569, in run_code\n",
      "    self.showtraceback(running_compiled_code=True)\n",
      "  File \"D:\\Software\\anaconda3\\envs\\newtf115\\lib\\site-packages\\IPython\\core\\interactiveshell.py\", line 2101, in showtraceback\n",
      "    value, tb, tb_offset=tb_offset)\n",
      "  File \"D:\\Software\\anaconda3\\envs\\newtf115\\lib\\site-packages\\IPython\\core\\ultratb.py\", line 1368, in structured_traceback\n",
      "    self, etype, value, tb, tb_offset, number_of_lines_of_context)\n",
      "  File \"D:\\Software\\anaconda3\\envs\\newtf115\\lib\\site-packages\\IPython\\core\\ultratb.py\", line 1268, in structured_traceback\n",
      "    self, etype, value, tb, tb_offset, number_of_lines_of_context\n",
      "  File \"D:\\Software\\anaconda3\\envs\\newtf115\\lib\\site-packages\\IPython\\core\\ultratb.py\", line 1125, in structured_traceback\n",
      "    tb_offset)\n",
      "  File \"D:\\Software\\anaconda3\\envs\\newtf115\\lib\\site-packages\\IPython\\core\\ultratb.py\", line 1082, in format_exception_as_a_whole\n",
      "    last_unique, recursion_repeat = find_recursion(orig_etype, evalue, records)\n",
      "  File \"D:\\Software\\anaconda3\\envs\\newtf115\\lib\\site-packages\\IPython\\core\\ultratb.py\", line 382, in find_recursion\n",
      "    return len(records), 0\n",
      "TypeError: object of type 'NoneType' has no len()\n",
      "\n",
      "During handling of the above exception, another exception occurred:\n",
      "\n",
      "Traceback (most recent call last):\n",
      "  File \"D:\\Software\\anaconda3\\envs\\newtf115\\lib\\site-packages\\IPython\\core\\interactiveshell.py\", line 2098, in showtraceback\n",
      "    stb = value._render_traceback_()\n",
      "AttributeError: 'TypeError' object has no attribute '_render_traceback_'\n",
      "\n",
      "During handling of the above exception, another exception occurred:\n",
      "\n",
      "Traceback (most recent call last):\n",
      "  File \"D:\\Software\\anaconda3\\envs\\newtf115\\lib\\site-packages\\IPython\\core\\ultratb.py\", line 1101, in get_records\n",
      "    return _fixed_getinnerframes(etb, number_of_lines_of_context, tb_offset)\n",
      "  File \"D:\\Software\\anaconda3\\envs\\newtf115\\lib\\site-packages\\IPython\\core\\ultratb.py\", line 248, in wrapped\n",
      "    return f(*args, **kwargs)\n",
      "  File \"D:\\Software\\anaconda3\\envs\\newtf115\\lib\\site-packages\\IPython\\core\\ultratb.py\", line 281, in _fixed_getinnerframes\n",
      "    records = fix_frame_records_filenames(inspect.getinnerframes(etb, context))\n",
      "  File \"D:\\Software\\anaconda3\\envs\\newtf115\\lib\\inspect.py\", line 1502, in getinnerframes\n",
      "    frameinfo = (tb.tb_frame,) + getframeinfo(tb, context)\n",
      "  File \"D:\\Software\\anaconda3\\envs\\newtf115\\lib\\inspect.py\", line 1460, in getframeinfo\n",
      "    filename = getsourcefile(frame) or getfile(frame)\n",
      "  File \"D:\\Software\\anaconda3\\envs\\newtf115\\lib\\inspect.py\", line 696, in getsourcefile\n",
      "    if getattr(getmodule(object, filename), '__loader__', None) is not None:\n",
      "  File \"D:\\Software\\anaconda3\\envs\\newtf115\\lib\\inspect.py\", line 733, in getmodule\n",
      "    if ismodule(module) and hasattr(module, '__file__'):\n",
      "  File \"D:\\Software\\anaconda3\\envs\\newtf115\\lib\\site-packages\\tensorflow\\__init__.py\", line 50, in __getattr__\n",
      "    module = self._load()\n",
      "  File \"D:\\Software\\anaconda3\\envs\\newtf115\\lib\\site-packages\\tensorflow\\__init__.py\", line 44, in _load\n",
      "    module = _importlib.import_module(self.__name__)\n",
      "  File \"D:\\Software\\anaconda3\\envs\\newtf115\\lib\\importlib\\__init__.py\", line 127, in import_module\n",
      "    return _bootstrap._gcd_import(name[level:], package, level)\n",
      "  File \"<frozen importlib._bootstrap>\", line 1006, in _gcd_import\n",
      "  File \"<frozen importlib._bootstrap>\", line 983, in _find_and_load\n",
      "  File \"<frozen importlib._bootstrap>\", line 965, in _find_and_load_unlocked\n",
      "ModuleNotFoundError: No module named 'tensorflow_core.estimator'\n",
      "Traceback (most recent call last):\n",
      "  File \"D:\\Software\\anaconda3\\envs\\newtf115\\lib\\site-packages\\IPython\\core\\interactiveshell.py\", line 3552, in run_code\n",
      "    exec(code_obj, self.user_global_ns, self.user_ns)\n",
      "  File \"C:\\Users\\wpkks\\AppData\\Local\\Temp\\ipykernel_29516\\2917289970.py\", line 2, in <module>\n",
      "    dataset_debiasing_train = debiased_model.predict_with_load_gra(dataset_orig_train)\n",
      "  File \"D:\\PycharmProjects\\AIF360\\aif360\\algorithms\\transformer.py\", line 27, in wrapper\n",
      "    new_dataset = func(self, *args, **kwargs)\n",
      "  File \"D:\\PycharmProjects\\AIF360\\aif360\\algorithms\\inprocessing\\adversarial_debiasing_dnn5.py\", line 513, in predict_with_load_gra\n",
      "    self.fit_without_train(dataset)\n",
      "  File \"D:\\PycharmProjects\\AIF360\\aif360\\algorithms\\transformer.py\", line 27, in wrapper\n",
      "    new_dataset = func(self, *args, **kwargs)\n",
      "  File \"D:\\PycharmProjects\\AIF360\\aif360\\algorithms\\inprocessing\\adversarial_debiasing_dnn5.py\", line 298, in fit_without_train\n",
      "    pred_protected_attributes_labels, pred_protected_attributes_logits = self._adversary_model(pred_logits, self.true_labels_ph)\n",
      "  File \"D:\\PycharmProjects\\AIF360\\aif360\\algorithms\\inprocessing\\adversarial_debiasing_dnn5.py\", line 84, in _adversary_model\n",
      "    c = tf.get_variable('c', initializer=tf.constant(1.0))\n",
      "  File \"D:\\Software\\anaconda3\\envs\\newtf115\\lib\\site-packages\\tensorflow_core\\python\\ops\\variable_scope.py\", line 1500, in get_variable\n",
      "    aggregation=aggregation)\n",
      "  File \"D:\\Software\\anaconda3\\envs\\newtf115\\lib\\site-packages\\tensorflow_core\\python\\ops\\variable_scope.py\", line 1243, in get_variable\n",
      "    aggregation=aggregation)\n",
      "  File \"D:\\Software\\anaconda3\\envs\\newtf115\\lib\\site-packages\\tensorflow_core\\python\\ops\\variable_scope.py\", line 567, in get_variable\n",
      "    aggregation=aggregation)\n",
      "  File \"D:\\Software\\anaconda3\\envs\\newtf115\\lib\\site-packages\\tensorflow_core\\python\\ops\\variable_scope.py\", line 519, in _true_getter\n",
      "    aggregation=aggregation)\n",
      "  File \"D:\\Software\\anaconda3\\envs\\newtf115\\lib\\site-packages\\tensorflow_core\\python\\ops\\variable_scope.py\", line 868, in _get_single_variable\n",
      "    (err_msg, \"\".join(traceback.format_list(tb))))\n",
      "ValueError: Variable debiased_classifier/adversary_model/c already exists, disallowed. Did you mean to set reuse=True or reuse=tf.AUTO_REUSE in VarScope? Originally defined at:\n",
      "\n",
      "  File \"D:\\Software\\anaconda3\\envs\\newtf115\\lib\\site-packages\\tensorflow_core\\python\\framework\\ops.py\", line 1748, in __init__\n",
      "    self._traceback = tf_stack.extract_stack()\n",
      "  File \"D:\\Software\\anaconda3\\envs\\newtf115\\lib\\site-packages\\tensorflow_core\\python\\framework\\ops.py\", line 3426, in _create_op_internal\n",
      "    op_def=op_def)\n",
      "  File \"D:\\Software\\anaconda3\\envs\\newtf115\\lib\\site-packages\\tensorflow_core\\python\\framework\\ops.py\", line 3357, in create_op\n",
      "    attrs, op_def, compute_device)\n",
      "  File \"D:\\Software\\anaconda3\\envs\\newtf115\\lib\\site-packages\\tensorflow_core\\python\\util\\deprecation.py\", line 507, in new_func\n",
      "    return func(*args, **kwargs)\n",
      "  File \"D:\\Software\\anaconda3\\envs\\newtf115\\lib\\site-packages\\tensorflow_core\\python\\framework\\op_def_library.py\", line 794, in _apply_op_helper\n",
      "    op_def=op_def)\n",
      "\n",
      "\n",
      "During handling of the above exception, another exception occurred:\n",
      "\n",
      "Traceback (most recent call last):\n",
      "  File \"D:\\Software\\anaconda3\\envs\\newtf115\\lib\\site-packages\\IPython\\core\\interactiveshell.py\", line 2098, in showtraceback\n",
      "    stb = value._render_traceback_()\n",
      "AttributeError: 'ValueError' object has no attribute '_render_traceback_'\n",
      "\n",
      "During handling of the above exception, another exception occurred:\n",
      "\n",
      "Traceback (most recent call last):\n",
      "  File \"D:\\Software\\anaconda3\\envs\\newtf115\\lib\\site-packages\\IPython\\core\\interactiveshell.py\", line 3472, in run_ast_nodes\n",
      "    if (await self.run_code(code, result,  async_=asy)):\n",
      "  File \"D:\\Software\\anaconda3\\envs\\newtf115\\lib\\site-packages\\IPython\\core\\interactiveshell.py\", line 3569, in run_code\n",
      "    self.showtraceback(running_compiled_code=True)\n",
      "  File \"D:\\Software\\anaconda3\\envs\\newtf115\\lib\\site-packages\\IPython\\core\\interactiveshell.py\", line 2101, in showtraceback\n",
      "    value, tb, tb_offset=tb_offset)\n",
      "  File \"D:\\Software\\anaconda3\\envs\\newtf115\\lib\\site-packages\\IPython\\core\\ultratb.py\", line 1368, in structured_traceback\n",
      "    self, etype, value, tb, tb_offset, number_of_lines_of_context)\n",
      "  File \"D:\\Software\\anaconda3\\envs\\newtf115\\lib\\site-packages\\IPython\\core\\ultratb.py\", line 1268, in structured_traceback\n",
      "    self, etype, value, tb, tb_offset, number_of_lines_of_context\n",
      "  File \"D:\\Software\\anaconda3\\envs\\newtf115\\lib\\site-packages\\IPython\\core\\ultratb.py\", line 1125, in structured_traceback\n",
      "    tb_offset)\n",
      "  File \"D:\\Software\\anaconda3\\envs\\newtf115\\lib\\site-packages\\IPython\\core\\ultratb.py\", line 1082, in format_exception_as_a_whole\n",
      "    last_unique, recursion_repeat = find_recursion(orig_etype, evalue, records)\n",
      "  File \"D:\\Software\\anaconda3\\envs\\newtf115\\lib\\site-packages\\IPython\\core\\ultratb.py\", line 382, in find_recursion\n",
      "    return len(records), 0\n",
      "TypeError: object of type 'NoneType' has no len()\n",
      "\n",
      "During handling of the above exception, another exception occurred:\n",
      "\n",
      "Traceback (most recent call last):\n",
      "  File \"D:\\Software\\anaconda3\\envs\\newtf115\\lib\\site-packages\\IPython\\core\\interactiveshell.py\", line 2098, in showtraceback\n",
      "    stb = value._render_traceback_()\n",
      "AttributeError: 'TypeError' object has no attribute '_render_traceback_'\n",
      "\n",
      "During handling of the above exception, another exception occurred:\n",
      "\n",
      "Traceback (most recent call last):\n",
      "  File \"D:\\Software\\anaconda3\\envs\\newtf115\\lib\\site-packages\\IPython\\core\\interactiveshell.py\", line 3029, in _run_cell\n",
      "    return runner(coro)\n",
      "  File \"D:\\Software\\anaconda3\\envs\\newtf115\\lib\\site-packages\\IPython\\core\\async_helpers.py\", line 78, in _pseudo_sync_runner\n",
      "    coro.send(None)\n",
      "  File \"D:\\Software\\anaconda3\\envs\\newtf115\\lib\\site-packages\\IPython\\core\\interactiveshell.py\", line 3257, in run_cell_async\n",
      "    interactivity=interactivity, compiler=compiler, result=result)\n",
      "  File \"D:\\Software\\anaconda3\\envs\\newtf115\\lib\\site-packages\\IPython\\core\\interactiveshell.py\", line 3491, in run_ast_nodes\n",
      "    self.showtraceback()\n",
      "  File \"D:\\Software\\anaconda3\\envs\\newtf115\\lib\\site-packages\\IPython\\core\\interactiveshell.py\", line 2101, in showtraceback\n",
      "    value, tb, tb_offset=tb_offset)\n",
      "  File \"D:\\Software\\anaconda3\\envs\\newtf115\\lib\\site-packages\\IPython\\core\\ultratb.py\", line 1368, in structured_traceback\n",
      "    self, etype, value, tb, tb_offset, number_of_lines_of_context)\n",
      "  File \"D:\\Software\\anaconda3\\envs\\newtf115\\lib\\site-packages\\IPython\\core\\ultratb.py\", line 1268, in structured_traceback\n",
      "    self, etype, value, tb, tb_offset, number_of_lines_of_context\n",
      "  File \"D:\\Software\\anaconda3\\envs\\newtf115\\lib\\site-packages\\IPython\\core\\ultratb.py\", line 1143, in structured_traceback\n",
      "    chained_exceptions_tb_offset)\n",
      "  File \"D:\\Software\\anaconda3\\envs\\newtf115\\lib\\site-packages\\IPython\\core\\ultratb.py\", line 1082, in format_exception_as_a_whole\n",
      "    last_unique, recursion_repeat = find_recursion(orig_etype, evalue, records)\n",
      "  File \"D:\\Software\\anaconda3\\envs\\newtf115\\lib\\site-packages\\IPython\\core\\ultratb.py\", line 382, in find_recursion\n",
      "    return len(records), 0\n",
      "TypeError: object of type 'NoneType' has no len()\n",
      "\n",
      "During handling of the above exception, another exception occurred:\n",
      "\n",
      "Traceback (most recent call last):\n",
      "  File \"D:\\Software\\anaconda3\\envs\\newtf115\\lib\\site-packages\\IPython\\core\\interactiveshell.py\", line 2098, in showtraceback\n",
      "    stb = value._render_traceback_()\n",
      "AttributeError: 'TypeError' object has no attribute '_render_traceback_'\n",
      "\n",
      "During handling of the above exception, another exception occurred:\n",
      "\n",
      "Traceback (most recent call last):\n",
      "  File \"D:\\Software\\anaconda3\\envs\\newtf115\\lib\\site-packages\\IPython\\core\\ultratb.py\", line 1101, in get_records\n",
      "    return _fixed_getinnerframes(etb, number_of_lines_of_context, tb_offset)\n",
      "  File \"D:\\Software\\anaconda3\\envs\\newtf115\\lib\\site-packages\\IPython\\core\\ultratb.py\", line 248, in wrapped\n",
      "    return f(*args, **kwargs)\n",
      "  File \"D:\\Software\\anaconda3\\envs\\newtf115\\lib\\site-packages\\IPython\\core\\ultratb.py\", line 281, in _fixed_getinnerframes\n",
      "    records = fix_frame_records_filenames(inspect.getinnerframes(etb, context))\n",
      "  File \"D:\\Software\\anaconda3\\envs\\newtf115\\lib\\inspect.py\", line 1502, in getinnerframes\n",
      "    frameinfo = (tb.tb_frame,) + getframeinfo(tb, context)\n",
      "  File \"D:\\Software\\anaconda3\\envs\\newtf115\\lib\\inspect.py\", line 1460, in getframeinfo\n",
      "    filename = getsourcefile(frame) or getfile(frame)\n",
      "  File \"D:\\Software\\anaconda3\\envs\\newtf115\\lib\\inspect.py\", line 696, in getsourcefile\n",
      "    if getattr(getmodule(object, filename), '__loader__', None) is not None:\n",
      "  File \"D:\\Software\\anaconda3\\envs\\newtf115\\lib\\inspect.py\", line 733, in getmodule\n",
      "    if ismodule(module) and hasattr(module, '__file__'):\n",
      "  File \"D:\\Software\\anaconda3\\envs\\newtf115\\lib\\site-packages\\tensorflow\\__init__.py\", line 50, in __getattr__\n",
      "    module = self._load()\n",
      "  File \"D:\\Software\\anaconda3\\envs\\newtf115\\lib\\site-packages\\tensorflow\\__init__.py\", line 44, in _load\n",
      "    module = _importlib.import_module(self.__name__)\n",
      "  File \"D:\\Software\\anaconda3\\envs\\newtf115\\lib\\importlib\\__init__.py\", line 127, in import_module\n",
      "    return _bootstrap._gcd_import(name[level:], package, level)\n",
      "  File \"<frozen importlib._bootstrap>\", line 1006, in _gcd_import\n",
      "  File \"<frozen importlib._bootstrap>\", line 983, in _find_and_load\n",
      "  File \"<frozen importlib._bootstrap>\", line 965, in _find_and_load_unlocked\n",
      "ModuleNotFoundError: No module named 'tensorflow_core.estimator'\n"
     ]
    }
   ],
   "source": [
    "# Apply the plain model to test data\n",
    "dataset_debiasing_train = debiased_model.predict_with_load_gra(dataset_orig_train)\n",
    "dataset_debiasing_test = debiased_model.predict_with_load_gra(dataset_orig_test)"
   ]
  },
  {
   "cell_type": "code",
   "execution_count": null,
   "metadata": {
    "pycharm": {
     "is_executing": true
    }
   },
   "outputs": [
    {
     "data": {
      "text/plain": "<IPython.core.display.Markdown object>",
      "text/markdown": "#### Plain model - without debiasing - dataset metrics"
     },
     "metadata": {},
     "output_type": "display_data"
    },
    {
     "name": "stdout",
     "output_type": "stream",
     "text": [
      "Train set: Difference in mean outcomes between unprivileged and privileged groups = 0.000000\n",
      "Test set: Difference in mean outcomes between unprivileged and privileged groups = 0.000000\n"
     ]
    },
    {
     "data": {
      "text/plain": "<IPython.core.display.Markdown object>",
      "text/markdown": "#### Model - with debiasing - dataset metrics"
     },
     "metadata": {},
     "output_type": "display_data"
    },
    {
     "name": "stderr",
     "output_type": "stream",
     "text": [
      "ERROR:root:Internal Python error in the inspect module.\n",
      "Below is the traceback from this internal error.\n",
      "\n",
      "ERROR:root:Internal Python error in the inspect module.\n",
      "Below is the traceback from this internal error.\n",
      "\n",
      "ERROR:root:Internal Python error in the inspect module.\n",
      "Below is the traceback from this internal error.\n",
      "\n"
     ]
    },
    {
     "name": "stdout",
     "output_type": "stream",
     "text": [
      "ERROR! Session/line number was not unique in database. History logging moved to new session 120\n",
      "Traceback (most recent call last):\n",
      "  File \"D:\\Software\\anaconda3\\envs\\newtf115\\lib\\site-packages\\IPython\\core\\interactiveshell.py\", line 3552, in run_code\n",
      "    exec(code_obj, self.user_global_ns, self.user_ns)\n",
      "  File \"C:\\Users\\wpkks\\AppData\\Local\\Temp\\ipykernel_29516\\3334198007.py\", line 8, in <module>\n",
      "    metric_dataset_debiasing_train = BinaryLabelDatasetMetric(dataset_debiasing_train,\n",
      "NameError: name 'dataset_debiasing_train' is not defined\n",
      "\n",
      "During handling of the above exception, another exception occurred:\n",
      "\n",
      "Traceback (most recent call last):\n",
      "  File \"D:\\Software\\anaconda3\\envs\\newtf115\\lib\\site-packages\\IPython\\core\\interactiveshell.py\", line 2098, in showtraceback\n",
      "    stb = value._render_traceback_()\n",
      "AttributeError: 'NameError' object has no attribute '_render_traceback_'\n",
      "\n",
      "During handling of the above exception, another exception occurred:\n",
      "\n",
      "Traceback (most recent call last):\n",
      "  File \"D:\\Software\\anaconda3\\envs\\newtf115\\lib\\site-packages\\IPython\\core\\ultratb.py\", line 1101, in get_records\n",
      "    return _fixed_getinnerframes(etb, number_of_lines_of_context, tb_offset)\n",
      "  File \"D:\\Software\\anaconda3\\envs\\newtf115\\lib\\site-packages\\IPython\\core\\ultratb.py\", line 248, in wrapped\n",
      "    return f(*args, **kwargs)\n",
      "  File \"D:\\Software\\anaconda3\\envs\\newtf115\\lib\\site-packages\\IPython\\core\\ultratb.py\", line 281, in _fixed_getinnerframes\n",
      "    records = fix_frame_records_filenames(inspect.getinnerframes(etb, context))\n",
      "  File \"D:\\Software\\anaconda3\\envs\\newtf115\\lib\\inspect.py\", line 1502, in getinnerframes\n",
      "    frameinfo = (tb.tb_frame,) + getframeinfo(tb, context)\n",
      "  File \"D:\\Software\\anaconda3\\envs\\newtf115\\lib\\inspect.py\", line 1460, in getframeinfo\n",
      "    filename = getsourcefile(frame) or getfile(frame)\n",
      "  File \"D:\\Software\\anaconda3\\envs\\newtf115\\lib\\inspect.py\", line 696, in getsourcefile\n",
      "    if getattr(getmodule(object, filename), '__loader__', None) is not None:\n",
      "  File \"D:\\Software\\anaconda3\\envs\\newtf115\\lib\\inspect.py\", line 733, in getmodule\n",
      "    if ismodule(module) and hasattr(module, '__file__'):\n",
      "  File \"D:\\Software\\anaconda3\\envs\\newtf115\\lib\\site-packages\\tensorflow\\__init__.py\", line 50, in __getattr__\n",
      "    module = self._load()\n",
      "  File \"D:\\Software\\anaconda3\\envs\\newtf115\\lib\\site-packages\\tensorflow\\__init__.py\", line 44, in _load\n",
      "    module = _importlib.import_module(self.__name__)\n",
      "  File \"D:\\Software\\anaconda3\\envs\\newtf115\\lib\\importlib\\__init__.py\", line 127, in import_module\n",
      "    return _bootstrap._gcd_import(name[level:], package, level)\n",
      "  File \"<frozen importlib._bootstrap>\", line 1006, in _gcd_import\n",
      "  File \"<frozen importlib._bootstrap>\", line 983, in _find_and_load\n",
      "  File \"<frozen importlib._bootstrap>\", line 965, in _find_and_load_unlocked\n",
      "ModuleNotFoundError: No module named 'tensorflow_core.estimator'\n",
      "Traceback (most recent call last):\n",
      "  File \"D:\\Software\\anaconda3\\envs\\newtf115\\lib\\site-packages\\IPython\\core\\interactiveshell.py\", line 3552, in run_code\n",
      "    exec(code_obj, self.user_global_ns, self.user_ns)\n",
      "  File \"C:\\Users\\wpkks\\AppData\\Local\\Temp\\ipykernel_29516\\3334198007.py\", line 8, in <module>\n",
      "    metric_dataset_debiasing_train = BinaryLabelDatasetMetric(dataset_debiasing_train,\n",
      "NameError: name 'dataset_debiasing_train' is not defined\n",
      "\n",
      "During handling of the above exception, another exception occurred:\n",
      "\n",
      "Traceback (most recent call last):\n",
      "  File \"D:\\Software\\anaconda3\\envs\\newtf115\\lib\\site-packages\\IPython\\core\\interactiveshell.py\", line 2098, in showtraceback\n",
      "    stb = value._render_traceback_()\n",
      "AttributeError: 'NameError' object has no attribute '_render_traceback_'\n",
      "\n",
      "During handling of the above exception, another exception occurred:\n",
      "\n",
      "Traceback (most recent call last):\n",
      "  File \"D:\\Software\\anaconda3\\envs\\newtf115\\lib\\site-packages\\IPython\\core\\interactiveshell.py\", line 3472, in run_ast_nodes\n",
      "    if (await self.run_code(code, result,  async_=asy)):\n",
      "  File \"D:\\Software\\anaconda3\\envs\\newtf115\\lib\\site-packages\\IPython\\core\\interactiveshell.py\", line 3569, in run_code\n",
      "    self.showtraceback(running_compiled_code=True)\n",
      "  File \"D:\\Software\\anaconda3\\envs\\newtf115\\lib\\site-packages\\IPython\\core\\interactiveshell.py\", line 2101, in showtraceback\n",
      "    value, tb, tb_offset=tb_offset)\n",
      "  File \"D:\\Software\\anaconda3\\envs\\newtf115\\lib\\site-packages\\IPython\\core\\ultratb.py\", line 1368, in structured_traceback\n",
      "    self, etype, value, tb, tb_offset, number_of_lines_of_context)\n",
      "  File \"D:\\Software\\anaconda3\\envs\\newtf115\\lib\\site-packages\\IPython\\core\\ultratb.py\", line 1268, in structured_traceback\n",
      "    self, etype, value, tb, tb_offset, number_of_lines_of_context\n",
      "  File \"D:\\Software\\anaconda3\\envs\\newtf115\\lib\\site-packages\\IPython\\core\\ultratb.py\", line 1125, in structured_traceback\n",
      "    tb_offset)\n",
      "  File \"D:\\Software\\anaconda3\\envs\\newtf115\\lib\\site-packages\\IPython\\core\\ultratb.py\", line 1082, in format_exception_as_a_whole\n",
      "    last_unique, recursion_repeat = find_recursion(orig_etype, evalue, records)\n",
      "  File \"D:\\Software\\anaconda3\\envs\\newtf115\\lib\\site-packages\\IPython\\core\\ultratb.py\", line 382, in find_recursion\n",
      "    return len(records), 0\n",
      "TypeError: object of type 'NoneType' has no len()\n",
      "\n",
      "During handling of the above exception, another exception occurred:\n",
      "\n",
      "Traceback (most recent call last):\n",
      "  File \"D:\\Software\\anaconda3\\envs\\newtf115\\lib\\site-packages\\IPython\\core\\interactiveshell.py\", line 2098, in showtraceback\n",
      "    stb = value._render_traceback_()\n",
      "AttributeError: 'TypeError' object has no attribute '_render_traceback_'\n",
      "\n",
      "During handling of the above exception, another exception occurred:\n",
      "\n",
      "Traceback (most recent call last):\n",
      "  File \"D:\\Software\\anaconda3\\envs\\newtf115\\lib\\site-packages\\IPython\\core\\ultratb.py\", line 1101, in get_records\n",
      "    return _fixed_getinnerframes(etb, number_of_lines_of_context, tb_offset)\n",
      "  File \"D:\\Software\\anaconda3\\envs\\newtf115\\lib\\site-packages\\IPython\\core\\ultratb.py\", line 248, in wrapped\n",
      "    return f(*args, **kwargs)\n",
      "  File \"D:\\Software\\anaconda3\\envs\\newtf115\\lib\\site-packages\\IPython\\core\\ultratb.py\", line 281, in _fixed_getinnerframes\n",
      "    records = fix_frame_records_filenames(inspect.getinnerframes(etb, context))\n",
      "  File \"D:\\Software\\anaconda3\\envs\\newtf115\\lib\\inspect.py\", line 1502, in getinnerframes\n",
      "    frameinfo = (tb.tb_frame,) + getframeinfo(tb, context)\n",
      "  File \"D:\\Software\\anaconda3\\envs\\newtf115\\lib\\inspect.py\", line 1460, in getframeinfo\n",
      "    filename = getsourcefile(frame) or getfile(frame)\n",
      "  File \"D:\\Software\\anaconda3\\envs\\newtf115\\lib\\inspect.py\", line 696, in getsourcefile\n",
      "    if getattr(getmodule(object, filename), '__loader__', None) is not None:\n",
      "  File \"D:\\Software\\anaconda3\\envs\\newtf115\\lib\\inspect.py\", line 733, in getmodule\n",
      "    if ismodule(module) and hasattr(module, '__file__'):\n",
      "  File \"D:\\Software\\anaconda3\\envs\\newtf115\\lib\\site-packages\\tensorflow\\__init__.py\", line 50, in __getattr__\n",
      "    module = self._load()\n",
      "  File \"D:\\Software\\anaconda3\\envs\\newtf115\\lib\\site-packages\\tensorflow\\__init__.py\", line 44, in _load\n",
      "    module = _importlib.import_module(self.__name__)\n",
      "  File \"D:\\Software\\anaconda3\\envs\\newtf115\\lib\\importlib\\__init__.py\", line 127, in import_module\n",
      "    return _bootstrap._gcd_import(name[level:], package, level)\n",
      "  File \"<frozen importlib._bootstrap>\", line 1006, in _gcd_import\n",
      "  File \"<frozen importlib._bootstrap>\", line 983, in _find_and_load\n",
      "  File \"<frozen importlib._bootstrap>\", line 965, in _find_and_load_unlocked\n",
      "ModuleNotFoundError: No module named 'tensorflow_core.estimator'\n",
      "Traceback (most recent call last):\n",
      "  File \"D:\\Software\\anaconda3\\envs\\newtf115\\lib\\site-packages\\IPython\\core\\interactiveshell.py\", line 3552, in run_code\n",
      "    exec(code_obj, self.user_global_ns, self.user_ns)\n",
      "  File \"C:\\Users\\wpkks\\AppData\\Local\\Temp\\ipykernel_29516\\3334198007.py\", line 8, in <module>\n",
      "    metric_dataset_debiasing_train = BinaryLabelDatasetMetric(dataset_debiasing_train,\n",
      "NameError: name 'dataset_debiasing_train' is not defined\n",
      "\n",
      "During handling of the above exception, another exception occurred:\n",
      "\n",
      "Traceback (most recent call last):\n",
      "  File \"D:\\Software\\anaconda3\\envs\\newtf115\\lib\\site-packages\\IPython\\core\\interactiveshell.py\", line 2098, in showtraceback\n",
      "    stb = value._render_traceback_()\n",
      "AttributeError: 'NameError' object has no attribute '_render_traceback_'\n",
      "\n",
      "During handling of the above exception, another exception occurred:\n",
      "\n",
      "Traceback (most recent call last):\n",
      "  File \"D:\\Software\\anaconda3\\envs\\newtf115\\lib\\site-packages\\IPython\\core\\interactiveshell.py\", line 3472, in run_ast_nodes\n",
      "    if (await self.run_code(code, result,  async_=asy)):\n",
      "  File \"D:\\Software\\anaconda3\\envs\\newtf115\\lib\\site-packages\\IPython\\core\\interactiveshell.py\", line 3569, in run_code\n",
      "    self.showtraceback(running_compiled_code=True)\n",
      "  File \"D:\\Software\\anaconda3\\envs\\newtf115\\lib\\site-packages\\IPython\\core\\interactiveshell.py\", line 2101, in showtraceback\n",
      "    value, tb, tb_offset=tb_offset)\n",
      "  File \"D:\\Software\\anaconda3\\envs\\newtf115\\lib\\site-packages\\IPython\\core\\ultratb.py\", line 1368, in structured_traceback\n",
      "    self, etype, value, tb, tb_offset, number_of_lines_of_context)\n",
      "  File \"D:\\Software\\anaconda3\\envs\\newtf115\\lib\\site-packages\\IPython\\core\\ultratb.py\", line 1268, in structured_traceback\n",
      "    self, etype, value, tb, tb_offset, number_of_lines_of_context\n",
      "  File \"D:\\Software\\anaconda3\\envs\\newtf115\\lib\\site-packages\\IPython\\core\\ultratb.py\", line 1125, in structured_traceback\n",
      "    tb_offset)\n",
      "  File \"D:\\Software\\anaconda3\\envs\\newtf115\\lib\\site-packages\\IPython\\core\\ultratb.py\", line 1082, in format_exception_as_a_whole\n",
      "    last_unique, recursion_repeat = find_recursion(orig_etype, evalue, records)\n",
      "  File \"D:\\Software\\anaconda3\\envs\\newtf115\\lib\\site-packages\\IPython\\core\\ultratb.py\", line 382, in find_recursion\n",
      "    return len(records), 0\n",
      "TypeError: object of type 'NoneType' has no len()\n",
      "\n",
      "During handling of the above exception, another exception occurred:\n",
      "\n",
      "Traceback (most recent call last):\n",
      "  File \"D:\\Software\\anaconda3\\envs\\newtf115\\lib\\site-packages\\IPython\\core\\interactiveshell.py\", line 2098, in showtraceback\n",
      "    stb = value._render_traceback_()\n",
      "AttributeError: 'TypeError' object has no attribute '_render_traceback_'\n",
      "\n",
      "During handling of the above exception, another exception occurred:\n",
      "\n",
      "Traceback (most recent call last):\n",
      "  File \"D:\\Software\\anaconda3\\envs\\newtf115\\lib\\site-packages\\IPython\\core\\interactiveshell.py\", line 3029, in _run_cell\n",
      "    return runner(coro)\n",
      "  File \"D:\\Software\\anaconda3\\envs\\newtf115\\lib\\site-packages\\IPython\\core\\async_helpers.py\", line 78, in _pseudo_sync_runner\n",
      "    coro.send(None)\n",
      "  File \"D:\\Software\\anaconda3\\envs\\newtf115\\lib\\site-packages\\IPython\\core\\interactiveshell.py\", line 3257, in run_cell_async\n",
      "    interactivity=interactivity, compiler=compiler, result=result)\n",
      "  File \"D:\\Software\\anaconda3\\envs\\newtf115\\lib\\site-packages\\IPython\\core\\interactiveshell.py\", line 3491, in run_ast_nodes\n",
      "    self.showtraceback()\n",
      "  File \"D:\\Software\\anaconda3\\envs\\newtf115\\lib\\site-packages\\IPython\\core\\interactiveshell.py\", line 2101, in showtraceback\n",
      "    value, tb, tb_offset=tb_offset)\n",
      "  File \"D:\\Software\\anaconda3\\envs\\newtf115\\lib\\site-packages\\IPython\\core\\ultratb.py\", line 1368, in structured_traceback\n",
      "    self, etype, value, tb, tb_offset, number_of_lines_of_context)\n",
      "  File \"D:\\Software\\anaconda3\\envs\\newtf115\\lib\\site-packages\\IPython\\core\\ultratb.py\", line 1268, in structured_traceback\n",
      "    self, etype, value, tb, tb_offset, number_of_lines_of_context\n",
      "  File \"D:\\Software\\anaconda3\\envs\\newtf115\\lib\\site-packages\\IPython\\core\\ultratb.py\", line 1143, in structured_traceback\n",
      "    chained_exceptions_tb_offset)\n",
      "  File \"D:\\Software\\anaconda3\\envs\\newtf115\\lib\\site-packages\\IPython\\core\\ultratb.py\", line 1082, in format_exception_as_a_whole\n",
      "    last_unique, recursion_repeat = find_recursion(orig_etype, evalue, records)\n",
      "  File \"D:\\Software\\anaconda3\\envs\\newtf115\\lib\\site-packages\\IPython\\core\\ultratb.py\", line 382, in find_recursion\n",
      "    return len(records), 0\n",
      "TypeError: object of type 'NoneType' has no len()\n",
      "\n",
      "During handling of the above exception, another exception occurred:\n",
      "\n",
      "Traceback (most recent call last):\n",
      "  File \"D:\\Software\\anaconda3\\envs\\newtf115\\lib\\site-packages\\IPython\\core\\interactiveshell.py\", line 2098, in showtraceback\n",
      "    stb = value._render_traceback_()\n",
      "AttributeError: 'TypeError' object has no attribute '_render_traceback_'\n",
      "\n",
      "During handling of the above exception, another exception occurred:\n",
      "\n",
      "Traceback (most recent call last):\n",
      "  File \"D:\\Software\\anaconda3\\envs\\newtf115\\lib\\site-packages\\IPython\\core\\ultratb.py\", line 1101, in get_records\n",
      "    return _fixed_getinnerframes(etb, number_of_lines_of_context, tb_offset)\n",
      "  File \"D:\\Software\\anaconda3\\envs\\newtf115\\lib\\site-packages\\IPython\\core\\ultratb.py\", line 248, in wrapped\n",
      "    return f(*args, **kwargs)\n",
      "  File \"D:\\Software\\anaconda3\\envs\\newtf115\\lib\\site-packages\\IPython\\core\\ultratb.py\", line 281, in _fixed_getinnerframes\n",
      "    records = fix_frame_records_filenames(inspect.getinnerframes(etb, context))\n",
      "  File \"D:\\Software\\anaconda3\\envs\\newtf115\\lib\\inspect.py\", line 1502, in getinnerframes\n",
      "    frameinfo = (tb.tb_frame,) + getframeinfo(tb, context)\n",
      "  File \"D:\\Software\\anaconda3\\envs\\newtf115\\lib\\inspect.py\", line 1460, in getframeinfo\n",
      "    filename = getsourcefile(frame) or getfile(frame)\n",
      "  File \"D:\\Software\\anaconda3\\envs\\newtf115\\lib\\inspect.py\", line 696, in getsourcefile\n",
      "    if getattr(getmodule(object, filename), '__loader__', None) is not None:\n",
      "  File \"D:\\Software\\anaconda3\\envs\\newtf115\\lib\\inspect.py\", line 733, in getmodule\n",
      "    if ismodule(module) and hasattr(module, '__file__'):\n",
      "  File \"D:\\Software\\anaconda3\\envs\\newtf115\\lib\\site-packages\\tensorflow\\__init__.py\", line 50, in __getattr__\n",
      "    module = self._load()\n",
      "  File \"D:\\Software\\anaconda3\\envs\\newtf115\\lib\\site-packages\\tensorflow\\__init__.py\", line 44, in _load\n",
      "    module = _importlib.import_module(self.__name__)\n",
      "  File \"D:\\Software\\anaconda3\\envs\\newtf115\\lib\\importlib\\__init__.py\", line 127, in import_module\n",
      "    return _bootstrap._gcd_import(name[level:], package, level)\n",
      "  File \"<frozen importlib._bootstrap>\", line 1006, in _gcd_import\n",
      "  File \"<frozen importlib._bootstrap>\", line 983, in _find_and_load\n",
      "  File \"<frozen importlib._bootstrap>\", line 965, in _find_and_load_unlocked\n",
      "ModuleNotFoundError: No module named 'tensorflow_core.estimator'\n"
     ]
    }
   ],
   "source": [
    "# Metrics for the dataset from plain model (without debiasing)\n",
    "display(Markdown(\"#### Plain model - without debiasing - dataset metrics\"))\n",
    "print(\"Train set: Difference in mean outcomes between unprivileged and privileged groups = %f\" % metric_dataset_nodebiasing_train.mean_difference())\n",
    "print(\"Test set: Difference in mean outcomes between unprivileged and privileged groups = %f\" % metric_dataset_nodebiasing_test.mean_difference())\n",
    "\n",
    "# Metrics for the dataset from model with debiasing\n",
    "display(Markdown(\"#### Model - with debiasing - dataset metrics\"))\n",
    "metric_dataset_debiasing_train = BinaryLabelDatasetMetric(dataset_debiasing_train, \n",
    "                                             unprivileged_groups=unprivileged_groups,\n",
    "                                             privileged_groups=privileged_groups)\n",
    "\n",
    "print(\"Train set: Difference in mean outcomes between unprivileged and privileged groups = %f\" % metric_dataset_debiasing_train.mean_difference())\n",
    "\n",
    "metric_dataset_debiasing_test = BinaryLabelDatasetMetric(dataset_debiasing_test, \n",
    "                                             unprivileged_groups=unprivileged_groups,\n",
    "                                             privileged_groups=privileged_groups)\n",
    "\n",
    "print(\"Test set: Difference in mean outcomes between unprivileged and privileged groups = %f\" % metric_dataset_debiasing_test.mean_difference())\n",
    "\n",
    "\n",
    "\n",
    "display(Markdown(\"#### Plain model - without debiasing - classification metrics\"))\n",
    "print(\"Test set: Classification accuracy = %f\" % classified_metric_nodebiasing_test.accuracy())\n",
    "TPR = classified_metric_nodebiasing_test.true_positive_rate()\n",
    "TNR = classified_metric_nodebiasing_test.true_negative_rate()\n",
    "bal_acc_nodebiasing_test = 0.5*(TPR+TNR)\n",
    "print(\"Test set: Balanced classification accuracy = %f\" % bal_acc_nodebiasing_test)\n",
    "print(\"Test set: Disparate impact = %f\" % classified_metric_nodebiasing_test.disparate_impact())\n",
    "print(\"Test set: Equal opportunity difference = %f\" % classified_metric_nodebiasing_test.equal_opportunity_difference())\n",
    "print(\"Test set: Average odds difference = %f\" % classified_metric_nodebiasing_test.average_odds_difference())\n",
    "print(\"Test set: Theil_index = %f\" % classified_metric_nodebiasing_test.theil_index())\n",
    "\n",
    "\n",
    "\n",
    "display(Markdown(\"#### Model - with debiasing - classification metrics\"))\n",
    "classified_metric_debiasing_test = ClassificationMetric(dataset_orig_test, \n",
    "                                                 dataset_debiasing_test,\n",
    "                                                 unprivileged_groups=unprivileged_groups,\n",
    "                                                 privileged_groups=privileged_groups)\n",
    "print(\"Test set: Classification accuracy = %f\" % classified_metric_debiasing_test.accuracy())\n",
    "TPR = classified_metric_debiasing_test.true_positive_rate()\n",
    "TNR = classified_metric_debiasing_test.true_negative_rate()\n",
    "bal_acc_debiasing_test = 0.5*(TPR+TNR)\n",
    "print(\"Test set: Balanced classification accuracy = %f\" % bal_acc_debiasing_test)\n",
    "print(\"Test set: Disparate impact = %f\" % classified_metric_debiasing_test.disparate_impact())\n",
    "print(\"Test set: Equal opportunity difference = %f\" % classified_metric_debiasing_test.equal_opportunity_difference())\n",
    "print(\"Test set: Average odds difference = %f\" % classified_metric_debiasing_test.average_odds_difference())\n",
    "print(\"Test set: Theil_index = %f\" % classified_metric_debiasing_test.theil_index())"
   ]
  },
  {
   "cell_type": "raw",
   "metadata": {
    "pycharm": {
     "name": "#%% raw\n"
    }
   },
   "source": [
    "\n",
    "    References:\n",
    "    [1] B. H. Zhang, B. Lemoine, and M. Mitchell, \"Mitigating UnwantedBiases with Adversarial Learning,\" \n",
    "    AAAI/ACM Conference on Artificial Intelligence, Ethics, and Society, 2018."
   ]
  },
  {
   "cell_type": "code",
   "execution_count": null,
   "metadata": {
    "collapsed": true
   },
   "outputs": [],
   "source": []
  }
 ],
 "metadata": {
  "kernelspec": {
   "display_name": "Python 3 (ipykernel)",
   "language": "python",
   "name": "python3"
  },
  "language_info": {
   "codemirror_mode": {
    "name": "ipython",
    "version": 3
   },
   "file_extension": ".py",
   "mimetype": "text/x-python",
   "name": "python",
   "nbconvert_exporter": "python",
   "pygments_lexer": "ipython3",
   "version": "3.7.12"
  }
 },
 "nbformat": 4,
 "nbformat_minor": 2
}